Workbook

Sheet Demands
A1: ifc_guid | B1: room_name | C1: media_type | D1: hvac_system_type | E1: kind | F1: value | G1: unit
A2: =Rooms!A2 -> 1e7aiH8Sn8fgWT34gsecs0 | B2: =Rooms!D2 -> Lagerraum | C2: HEI | D2: HEI | E2: LOAD | F2: =Rooms!P2 -> 300 | G2: W
A3: =Rooms!A2 -> 1e7aiH8Sn8fgWT34gsecs0 | B3: =Rooms!D2 -> Lagerraum | C3: LUE | D3: LUE | E3: FLOW | F3: =Rooms!Q2 -> 15 | G3: m3/h
A4: =Rooms!A3 -> 1AjrabScTD7QDGtcwTOelF | B4: =Rooms!D3 -> Lagerraum | C4: HEI | D4: HEI | E4: LOAD | F4: =Rooms!P3 -> 750 | G4: W
A5: =Rooms!A3 -> 1AjrabScTD7QDGtcwTOelF | B5: =Rooms!D3 -> Lagerraum | C5: LUE | D5: LUE | E5: FLOW | F5: =Rooms!Q3 -> 40 | G5: m3/h
A6: =Rooms!A5 -> 38ZWYAAYT3vu3w7nEOjRX9 | B6: =Rooms!D5 -> Hauswart | C6: HEI | D6: HEI | E6: LOAD | F6: =Rooms!P5 -> 1550 | G6: W
A7: =Rooms!A5 -> 38ZWYAAYT3vu3w7nEOjRX9 | B7: =Rooms!D5 -> Hauswart | C7: LUE | D7: LUE | E7: FLOW | F7: =Rooms!Q5 -> 100 | G7: m3/h
A8: =Rooms!A5 -> 38ZWYAAYT3vu3w7nEOjRX9 | B8: =Rooms!D5 -> Hauswart | C8: SAN | D8: SAN | E8: FLOW | F8: =Rooms!R5 -> 0.05 | G8: l/s
A9: =Rooms!A6 -> 0WXx9SLDn4veY22LFyMZpR | B9: =Rooms!D6 -> Lagerraum | C9: HEI | D9: HEI | E9: LOAD | F9: =Rooms!P6 -> 750 | G9: W
A10: =Rooms!A6 -> 0WXx9SLDn4veY22LFyMZpR | B10: =Rooms!D6 -> Lagerraum | C10: LUE | D10: LUE | E10: FLOW | F10: =Rooms!Q6 -> 40 | G10: m3/h
A11: =Rooms!A8 -> 2fq$TLEG196gRjylkOPPt1 | B11: =Rooms!D8 -> Lagerraum | C11: HEI | D11: HEI | E11: LOAD | F11: =Rooms!P8 -> 750 | G11: W
A12: =Rooms!A8 -> 2fq$TLEG196gRjylkOPPt1 | B12: =Rooms!D8 -> Lagerraum | C12: LUE | D12: LUE | E12: FLOW | F12: =Rooms!Q8 -> 40 | G12: m3/h
A13: =Rooms!A13 -> 2Fd3QJrEL8KeGvReeX8pzg | B13: =Rooms!D13 -> WC Bad Dusche | C13: HEI | D13: HEI | E13: LOAD | F13: =Rooms!P13 -> 400 | G13: W
A14: =Rooms!A13 -> 2Fd3QJrEL8KeGvReeX8pzg | B14: =Rooms!D13 -> WC Bad Dusche | C14: LUE | D14: LUE | E14: FLOW | F14: =Rooms!Q13 -> 90 | G14: m3/h
A15: =Rooms!A13 -> 2Fd3QJrEL8KeGvReeX8pzg | B15: =Rooms!D13 -> WC Bad Dusche | C15: SAN | D15: SAN | E15: FLOW | F15: =Rooms!R13 -> 0.2 | G15: l/s
A16: =Rooms!A19 -> 2h1BgBjgT1de_eNsTp1uud | B16: =Rooms!D19 -> Sitzungszimmer | C16: HEI | D16: HEI | E16: LOAD | F16: =Rooms!P19 -> 3600 | G16: W
A17: =Rooms!A19 -> 2h1BgBjgT1de_eNsTp1uud | B17: =Rooms!D19 -> Sitzungszimmer | C17: LUE | D17: LUE | E17: FLOW | F17: =Rooms!Q19 -> 680 | G17: m3/h
A18: =Rooms!A20 -> 3SAD0c$KzCjwNFJKsTbYlX | B18: =Rooms!D20 -> Küche / Pausenraum | C18: HEI | D18: HEI | E18: LOAD | F18: =Rooms!P20 -> 3450 | G18: W
A19: =Rooms!A20 -> 3SAD0c$KzCjwNFJKsTbYlX | B19: =Rooms!D20 -> Küche / Pausenraum | C19: LUE | D19: LUE | E19: FLOW | F19: =Rooms!Q20 -> 375 | G19: m3/h
A20: =Rooms!A20 -> 3SAD0c$KzCjwNFJKsTbYlX | B20: =Rooms!D20 -> Küche / Pausenraum | C20: SAN | D20: SAN | E20: FLOW | F20: =Rooms!R20 -> 0.12 | G20: l/s
A21: =Rooms!A21 -> 07Q$ZAhHr9G9v1aKAjwyOA | B21: =Rooms!D21 -> Laborraum | C21: HEI | D21: HEI | E21: LOAD | F21: =Rooms!P21 -> 2850 | G21: W
A22: =Rooms!A21 -> 07Q$ZAhHr9G9v1aKAjwyOA | B22: =Rooms!D21 -> Laborraum | C22: LUE | D22: LUE | E22: FLOW | F22: =Rooms!Q21 -> 265 | G22: m3/h
A23: =Rooms!A21 -> 07Q$ZAhHr9G9v1aKAjwyOA | B23: =Rooms!D21 -> Laborraum | C23: SAN | D23: SAN | E23: FLOW | F23: =Rooms!R21 -> 0.05 | G23: l/s
A24: =Rooms!A22 -> 2pGZzOqrP3QgX198DnmsPP | B24: =Rooms!D22 -> Grossraumbüro | C24: HEI | D24: HEI | E24: LOAD | F24: =Rooms!P22 -> 4150 | G24: W
A25: =Rooms!A22 -> 2pGZzOqrP3QgX198DnmsPP | B25: =Rooms!D22 -> Grossraumbüro | C25: LUE | D25: LUE | E25: FLOW | F25: =Rooms!Q22 -> 395 | G25: m3/h
A26: =Rooms!A23 -> 015OTJ3jz9LfvJSOtjdwqK | B26: =Rooms!D23 -> Einzelbüro | C26: HEI | D26: HEI | E26: LOAD | F26: =Rooms!P23 -> 1750 | G26: W
A27: =Rooms!A23 -> 015OTJ3jz9LfvJSOtjdwqK | B27: =Rooms!D23 -> Einzelbüro | C27: LUE | D27: LUE | E27: FLOW | F27: =Rooms!Q23 -> 125 | G27: m3/h
A28: =Rooms!A24 -> 0qsyONUOnA7uV4ziubso__ | B28: =Rooms!D24 -> Grossraumbüro | C28: HEI | D28: HEI | E28: LOAD | F28: =Rooms!P24 -> 4850 | G28: W
A29: =Rooms!A24 -> 0qsyONUOnA7uV4ziubso__ | B29: =Rooms!D24 -> Grossraumbüro | C29: LUE | D29: LUE | E29: FLOW | F29: =Rooms!Q24 -> 470 | G29: m3/h
A30: =Rooms!A25 -> 2SamNHDVH87BoWSt7usIhV | B30: =Rooms!D25 -> Einzelbüro | C30: HEI | D30: HEI | E30: LOAD | F30: =Rooms!P25 -> 2200 | G30: W
A31: =Rooms!A25 -> 2SamNHDVH87BoWSt7usIhV | B31: =Rooms!D25 -> Einzelbüro | C31: LUE | D31: LUE | E31: FLOW | F31: =Rooms!Q25 -> 155 | G31: m3/h
A32: =Rooms!A26 -> 2RQfxNTAL9q9ncgRSekcCr | B32: =Rooms!D26 -> Grossraumbüro | C32: HEI | D32: HEI | E32: LOAD | F32: =Rooms!P26 -> 2900 | G32: W
A33: =Rooms!A26 -> 2RQfxNTAL9q9ncgRSekcCr | B33: =Rooms!D26 -> Grossraumbüro | C33: LUE | D33: LUE | E33: FLOW | F33: =Rooms!Q26 -> 290 | G33: m3/h
A34: =Rooms!A27 -> 0pgni$2or6XO_NrWyexSdA | B34: =Rooms!D27 -> Sitzungszimmer | C34: HEI | D34: HEI | E34: LOAD | F34: =Rooms!P27 -> 3600 | G34: W
A35: =Rooms!A27 -> 0pgni$2or6XO_NrWyexSdA | B35: =Rooms!D27 -> Sitzungszimmer | C35: LUE | D35: LUE | E35: FLOW | F35: =Rooms!Q27 -> 680 | G35: m3/h
A36: =Rooms!A28 -> 3zFj_sKlT5DxU$pSRK_gVt | B36: =Rooms!D28 -> Sitzungszimmer | C36: HEI | D36: HEI | E36: LOAD | F36: =Rooms!P28 -> 1550 | G36: W
A37: =Rooms!A28 -> 3zFj_sKlT5DxU$pSRK_gVt | B37: =Rooms!D28 -> Sitzungszimmer | C37: LUE | D37: LUE | E37: FLOW | F37: =Rooms!Q28 -> 320 | G37: m3/h
A38: =Rooms!A29 -> 3mL9nzYdLAm9c0EQUdM5fJ | B38: =Rooms!D29 -> Gruppenbüro | C38: HEI | D38: HEI | E38: LOAD | F38: =Rooms!P29 -> 3800 | G38: W
A39: =Rooms!A29 -> 3mL9nzYdLAm9c0EQUdM5fJ | B39: =Rooms!D29 -> Gruppenbüro | C39: LUE | D39: LUE | E39: FLOW | F39: =Rooms!Q29 -> 270 | G39: m3/h
A40: =Rooms!A30 -> 2pJJabSVnA7vCOzjrF1EXy | B40: =Rooms!D30 -> Gruppenbüro | C40: HEI | D40: HEI | E40: LOAD | F40: =Rooms!P30 -> 3800 | G40: W
...

Sheet Rooms
A1: ifc_guid | B1: storey | C1: room_code | D1: room_name | E1: area_m2 | F1: height_m | G1: heated_status | H1: occupancy | I1: category | J1: heat_w_m2 | K1: air_m3h_m2 | L1: air_m3h_person | M1: air_min_m3h | N1: water_default_ls | O1: water_override_ls | P1: HEI_W | Q1: LUE_m3h | R1: SAN_l/s | S1: note
A2: 1e7aiH8Sn8fgWT34gsecs0 | B2: UG | C2: 11 | D2: Lagerraum | E2: 28.35 | F2: 2.05 | G2: kalt | H2: 0 | I2: STORAGE | J2: 20 | K2: 0.5 | L2: 0 | M2: 10 | N2: 0 | P2: =IF(OR(I2="SHAFT",I2="LIFT"),0,IF(G2="unbeheizt",0,IF(G2="kalt",ROUND(E2*MIN(J2,10)/50,0)*50,ROUND(E2*J2/50,0)*50))) -> 300 | Q2: =IF(MAX(K2,L2,M2)=0,0,MAX(M2,ROUND(MAX(E2*K2,H2*L2)/5,0)*5)) -> 15 | R2: =ROUND(IF(O2<>"",O2,N2),2) -> 0 | S2: Estimated from IFC room name, occupancy type and area. OccupancyType: Lagerhalle.
A3: 1AjrabScTD7QDGtcwTOelF | B3: UG | C3: 12 | D3: Lagerraum | E3: 76.44 | F3: 2.05 | G3: kalt | H3: 0 | I3: STORAGE | J3: 20 | K3: 0.5 | L3: 0 | M3: 10 | N3: 0 | P3: =IF(OR(I3="SHAFT",I3="LIFT"),0,IF(G3="unbeheizt",0,IF(G3="kalt",ROUND(E3*MIN(J3,10)/50,0)*50,ROUND(E3*J3/50,0)*50))) -> 750 | Q3: =IF(MAX(K3,L3,M3)=0,0,MAX(M3,ROUND(MAX(E3*K3,H3*L3)/5,0)*5)) -> 40 | R3: =ROUND(IF(O3<>"",O3,N3),2) -> 0 | S3: Estimated from IFC room name, occupancy type and area. OccupancyType: Lagerhalle.
A4: 3hpHpkcUj9Vwf8TX00VY7$ | B4: UG | C4: 13 | D4: Technikzentrale | E4: 97.94 | F4: 2.05 | G4: unbeheizt | H4: 0 | I4: TECHNICAL | J4: 10 | K4: 1.5 | L4: 0 | M4: 20 | N4: 0 | P4: =IF(OR(I4="SHAFT",I4="LIFT"),0,IF(G4="unbeheizt",0,IF(G4="kalt",ROUND(E4*MIN(J4,10)/50,0)*50,ROUND(E4*J4/50,0)*50))) -> 0 | Q4: =IF(MAX(K4,L4,M4)=0,0,MAX(M4,ROUND(MAX(E4*K4,H4*L4)/5,0)*5)) -> 145 | R4: =ROUND(IF(O4<>"",O4,N4),2) -> 0 | S4: Estimated from IFC room name, occupancy type and area.
A5: 38ZWYAAYT3vu3w7nEOjRX9 | B5: UG | C5: 14 | D5: Hauswart | E5: 34.08 | F5: 2.05 | G5: beheizt | H5: 2 | I5: HOUSEKEEPING | J5: 45 | K5: 3 | L5: 20 | M5: 40 | N5: 0.05 | P5: =IF(OR(I5="SHAFT",I5="LIFT"),0,IF(G5="unbeheizt",0,IF(G5="kalt",ROUND(E5*MIN(J5,10)/50,0)*50,ROUND(E5*J5/50,0)*50))) -> 1550 | Q5: =IF(MAX(K5,L5,M5)=0,0,MAX(M5,ROUND(MAX(E5*K5,H5*L5)/5,0)*5)) -> 100 | R5: =ROUND(IF(O5<>"",O5,N5),2) -> 0.05 | S5: Estimated from IFC room name, occupancy type and area.
A6: 0WXx9SLDn4veY22LFyMZpR | B6: UG | C6: 15 | D6: Lagerraum | E6: 76.44 | F6: 2.05 | G6: kalt | H6: 0 | I6: STORAGE | J6: 20 | K6: 0.5 | L6: 0 | M6: 10 | N6: 0 | P6: =IF(OR(I6="SHAFT",I6="LIFT"),0,IF(G6="unbeheizt",0,IF(G6="kalt",ROUND(E6*MIN(J6,10)/50,0)*50,ROUND(E6*J6/50,0)*50))) -> 750 | Q6: =IF(MAX(K6,L6,M6)=0,0,MAX(M6,ROUND(MAX(E6*K6,H6*L6)/5,0)*5)) -> 40 | R6: =ROUND(IF(O6<>"",O6,N6),2) -> 0 | S6: Estimated from IFC room name, occupancy type and area. OccupancyType: Lagerhalle.
A7: 0X4Q7Ahhn9oBN510bvdGJ7 | B7: UG | C7: 16 | D7: Technikzentrale | E7: 99.84 | F7: 2.05 | G7: unbeheizt | H7: 0 | I7: TECHNICAL | J7: 10 | K7: 1.5 | L7: 0 | M7: 20 | N7: 0 | P7: =IF(OR(I7="SHAFT",I7="LIFT"),0,IF(G7="unbeheizt",0,IF(G7="kalt",ROUND(E7*MIN(J7,10)/50,0)*50,ROUND(E7*J7/50,0)*50))) -> 0 | Q7: =IF(MAX(K7,L7,M7)=0,0,MAX(M7,ROUND(MAX(E7*K7,H7*L7)/5,0)*5)) -> 150 | R7: =ROUND(IF(O7<>"",O7,N7),2) -> 0 | S7: Estimated from IFC room name, occupancy type and area.
A8: 2fq$TLEG196gRjylkOPPt1 | B8: UG | C8: 17 | D8: Lagerraum | E8: 76.44 | F8: 2.05 | G8: kalt | H8: 0 | I8: STORAGE | J8: 20 | K8: 0.5 | L8: 0 | M8: 10 | N8: 0 | P8: =IF(OR(I8="SHAFT",I8="LIFT"),0,IF(G8="unbeheizt",0,IF(G8="kalt",ROUND(E8*MIN(J8,10)/50,0)*50,ROUND(E8*J8/50,0)*50))) -> 750 | Q8: =IF(MAX(K8,L8,M8)=0,0,MAX(M8,ROUND(MAX(E8*K8,H8*L8)/5,0)*5)) -> 40 | R8: =ROUND(IF(O8<>"",O8,N8),2) -> 0 | S8: Estimated from IFC room name, occupancy type and area. OccupancyType: Lagerhalle.
A9: 0r0GK22SP4VvC6JLL1U4uW | B9: UG | C9: 23 | D9: Lift | E9: 21.6 | F9: 2.05 | G9: unbeheizt | H9: 0 | I9: LIFT | J9: 0 | K9: 0 | L9: 0 | M9: 0 | N9: 0 | P9: =IF(OR(I9="SHAFT",I9="LIFT"),0,IF(G9="unbeheizt",0,IF(G9="kalt",ROUND(E9*MIN(J9,10)/50,0)*50,ROUND(E9*J9/50,0)*50))) -> 0 | Q9: =IF(MAX(K9,L9,M9)=0,0,MAX(M9,ROUND(MAX(E9*K9,H9*L9)/5,0)*5)) -> 0 | R9: =ROUND(IF(O9<>"",O9,N9),2) -> 0 | S9: Estimated from IFC room name, occupancy type and area.
A10: 1n99Mc5s10ERHmxOHpNOCU | B10: UG | C10: 24 | D10: Treppenhaus | E10: 157.44 | F10: 2.05 | G10: kalt | H10: 0 | I10: STAIR | J10: 15 | K10: 1 | L10: 0 | M10: 15 | N10: 0 | P10: =IF(OR(I10="SHAFT",I10="LIFT"),0,IF(G10="unbeheizt",0,IF(G10="kalt",ROUND(E10*MIN(J10,10)/50,0)*50,ROUND(E10*J10/50,0)*50))) -> 1550 | Q10: =IF(MAX(K10,L10,M10)=0,0,MAX(M10,ROUND(MAX(E10*K10,H10*L10)/5,0)*5)) -> 155 | R10: =ROUND(IF(O10<>"",O10,N10),2) -> 0 | S10: Estimated from IFC room name, occupancy type and area. OccupancyType: Treppenhaus.
A11: 3FOeTu6pnBkexhLeeY6q63 | B11: UG | C11: 25 | D11: Korridor | E11: 99.84 | F11: 2.05 | G11: beheizt | H11: 0 | I11: CORRIDOR | J11: 25 | K11: 1.5 | L11: 0 | M11: 20 | N11: 0 | P11: =IF(OR(I11="SHAFT",I11="LIFT"),0,IF(G11="unbeheizt",0,IF(G11="kalt",ROUND(E11*MIN(J11,10)/50,0)*50,ROUND(E11*J11/50,0)*50))) -> 2500 | Q11: =IF(MAX(K11,L11,M11)=0,0,MAX(M11,ROUND(MAX(E11*K11,H11*L11)/5,0)*5)) -> 150 | R11: =ROUND(IF(O11<>"",O11,N11),2) -> 0 | S11: Estimated from IFC room name, occupancy type and area. OccupancyType: Verkehrsfläche.
A12: 1po6wfw1L6Du_SCcMQzf0s | B12: UG | C12: 26 | D12: Korridor | E12: 11.04 | F12: 2.05 | G12: beheizt | H12: 0 | I12: CORRIDOR | J12: 25 | K12: 1.5 | L12: 0 | M12: 20 | N12: 0 | P12: =IF(OR(I12="SHAFT",I12="LIFT"),0,IF(G12="unbeheizt",0,IF(G12="kalt",ROUND(E12*MIN(J12,10)/50,0)*50,ROUND(E12*J12/50,0)*50))) -> 300 | Q12: =IF(MAX(K12,L12,M12)=0,0,MAX(M12,ROUND(MAX(E12*K12,H12*L12)/5,0)*5)) -> 20 | R12: =ROUND(IF(O12<>"",O12,N12),2) -> 0 | S12: Estimated from IFC room name, occupancy type and area. OccupancyType: Verkehrsfläche.
A13: 2Fd3QJrEL8KeGvReeX8pzg | B13: UG | C13: 32 | D13: WC Bad Dusche | E13: 11.04 | F13: 2.05 | G13: beheizt | H13: 0 | I13: SANITARY | J13: 35 | K13: 8 | L13: 0 | M13: 60 | N13: 0.2 | P13: =IF(OR(I13="SHAFT",I13="LIFT"),0,IF(G13="unbeheizt",0,IF(G13="kalt",ROUND(E13*MIN(J13,10)/50,0)*50,ROUND(E13*J13/50,0)*50))) -> 400 | Q13: =IF(MAX(K13,L13,M13)=0,0,MAX(M13,ROUND(MAX(E13*K13,H13*L13)/5,0)*5)) -> 90 | R13: =ROUND(IF(O13<>"",O13,N13),2) -> 0.2 | S13: Estimated from IFC room name, occupancy type and area. OccupancyType: WC, Bad, Dusche.
... A108: 1f$1icVJ9F8gLfub5rtniV | B108: 2.OG | C108: 45 | D108: Schacht | E108: 6.24 | F108: 2.05 | G108: unbeheizt | H108: 0 | I108: SHAFT | J108: 0 | K108: 0 | L108: 0 | M108: 0 | N108: 0 | P108: =IF(OR(I108="SHAFT",I108="LIFT"),0,IF(G108="unbeheizt",0,IF(G108="kalt",ROUND(E108*MIN(J108,10)/50,0)*50,ROUND(E108*J108/50,0)*50))) -> 0 | Q108: =IF(MAX(K108,L108,M108)=0,0,MAX(M108,ROUND(MAX(E108*K108,H108*L108)/5,0)*5)) -> 0 | R108: =ROUND(IF(O108<>"",O108,N108),2) -> 0 | S108: Estimated from IFC room name, occupancy type and area.

Sheet Assumptions
A1: category | B1: heat_w_m2 | C1: air_m3h_m2 | D1: air_m3h_person | E1: air_min_m3h | F1: water_default_ls | G1: description
A2: OFFICE | B2: 50 | C2: 3.5 | D2: 36 | E2: 40 | F2: 0 | G2: Enclosed offices and group offices
A3: OPEN_OFFICE | B3: 50 | C3: 4 | D3: 36 | E3: 60 | F3: 0 | G3: Open-plan office space
A4: MEETING | B4: 55 | C4: 4.5 | D4: 40 | E4: 60 | F4: 0 | G4: Meeting and seminar rooms
A5: LAB | B5: 65 | C5: 6 | D5: 50 | E5: 120 | F5: 0.05 | G5: Laboratory / practical rooms
A6: KITCHEN_BREAK | B6: 60 | C6: 6.5 | D6: 20 | E6: 150 | F6: 0.12 | G6: Kitchenette and break room
A7: SANITARY | B7: 35 | C7: 8 | D7: 0 | E7: 60 | F7: 0.2 | G7: WC / shower / washroom
A8: WARDROBE | B8: 30 | C8: 4 | D8: 0 | E8: 40 | F8: 0.1 | G8: Changing room / wardrobe
A9: HOUSEKEEPING | B9: 45 | C9: 3 | D9: 20 | E9: 40 | F9: 0.05 | G9: Janitor / service room
A10: CORRIDOR | B10: 25 | C10: 1.5 | D10: 0 | E10: 20 | F10: 0 | G10: Circulation corridor
A11: STAIR | B11: 15 | C11: 1 | D11: 0 | E11: 15 | F11: 0 | G11: Stairwell
A12: STORAGE | B12: 20 | C12: 0.5 | D12: 0 | E12: 10 | F12: 0 | G12: Storage rooms
A13: TECHNICAL | B13: 10 | C13: 1.5 | D13: 0 | E13: 20 | F13: 0 | G13: Technical / plant rooms
... A15: LIFT | B15: 0 | C15: 0 | D15: 0 | E15: 0 | F15: 0 | G15: Lift / elevator core
